Workbook

Sheet GORE
A1: PRESUPUESTO OFICIAL — PROYECTO LUZ EN CASA · GORE COQUIMBO
A2: Financiamiento FNDR Subtítulo 33 · 75 sistemas FV domiciliarios · Cofinanciamiento 50% / 50%
B5: Ítem / Descripción | C5: Ago 2026 | D5: Sep 2026 | E5: Oct 2026 | F5: Nov 2026 | G5: Dic 2026 | H5: Ene 2027 | I5: Feb 2027 | J5: TOTAL | L5: GORE | M5: FUNDACIÓN
A6: 1 | B6: Diagnóstico general y catastro básico de hogares en La Higuera | C6: =+'Valorización Componentes'!C4 | D6: =+'Valorización Componentes'!D4 | E6: =+'Valorización Componentes'!E4 | F6: =+'Valorización Componentes'!F4 | G6: =+'Valorización Componentes'!G4 | H6: =+'Valorización Componentes'!H4 | I6: =+'Valorización Componentes'!I4 | J6: =SUM(C4:I4) | L6: =+J4
B7: Levantamiento y revisión de antecedentes territoriales, sociales y energéticos 90 km radio desde La Serena
B8: Revisión preliminar de sectores, localidades y hogares potencialmente beneficiarios del programa.
B9: Elaboración del informe de diagnóstico general y universo inicial de hogares a catastrar.
A10: 2 | B10: Catastro georeferenciado uno a uno de viviendas | C10: =+'Valorización Componentes'!C22 | D10: =+'Valorización Componentes'!D22 | E10: =+'Valorización Componentes'!E22 | F10: =+'Valorización Componentes'!F22 | G10: =+'Valorización Componentes'!G22 | H10: =+'Valorización Componentes'!H22 | I10: =+'Valorización Componentes'!I22 | J10: =SUM(C8:I8) | L10: =+J8
B11: Planificación de rutas, sectores de visita y metodología de levantamiento georreferenciado.
B12: Aplicación de ficha de catastro vivienda a vivienda, incluyendo ubicación, condición habitacional y situación energética.
B13: Consolidación de base de datos georreferenciada, respaldo fotográfico y mapa de viviendas catastradas.
A14: 3 | B14: Verificación y sensibilización de usuarios catastrados. Incorporación de beneficiarios a programa de instalación. | C14: =+'Valorización Componentes'!C40 | D14: =+'Valorización Componentes'!D40 | E14: =+'Valorización Componentes'!E40 | F14: =+'Valorización Componentes'!F40 | G14: =+'Valorización Componentes'!G40 | H14: =+'Valorización Componentes'!H40 | I14: =+'Valorización Componentes'!I40 | J14: =SUM(C12:I12) | L14: =+J12
B15: Verificación en terreno de antecedentes levantados en el catastro y validación de cumplimiento de criterios de elegibilidad.
B16: Ejecución de jornadas de sensibilización sobre alcances del programa, condiciones de participación y responsabilidades del usuario.
B17: Elaboración de nómina final de beneficiarios e incorporación formal de usuarios al programa de instalación.
A18: 4 | B18: Capacitación de sistemas ERNC usuarios beneficiario. | C18: =+'Valorización Componentes'!C59 | D18: =+'Valorización Componentes'!D59 | E18: =+'Valorización Componentes'!E59 | F18: =+'Valorización Componentes'!F59 | G18: =+'Valorización Componentes'!G59 | H18: =+'Valorización Componentes'!H59 | I18: =+'Valorización Componentes'!I59 | J18: =SUM(C16:I16) | L18: =+J16
B19: Diseño de contenidos de capacitación sobre funcionamiento básico, seguridad y cuidados de sistemas ERNC domiciliarios.
B20: Realización de talleres prácticos para usuarios beneficiarios sobre operación diaria del sistema.
B21: Evaluación de comprensión de usuarios y entrega de material de apoyo para uso y cuidado del sistema.
A22: 5 | B22: Implementacion del un modelo de mantenimiento a 10 años | C22: =SUM(C21:C22) | D22: =SUM(D21:D22) | E22: =SUM(E21:E22) | F22: =SUM(F21:F22) | G22: =SUM(G21:G22) | H22: =SUM(H21:H22) | I22: =SUM(I21:I22) | J22: =SUM(C20:I20) | L22: =+J20
B23: Prograna de mantenimiento operativo | F23: =+'Valorización Componentes'!F77
B24: Programa de reposición | I24: =+'Valorización Componentes'!I77 | J24: =SUM(C22:I22) | M24: =+J22
A25: 6 | B25: Sistemas ERNC | C25: =+C24+C25 | D25: =+D24+D25 | E25: =+E24+E25 | F25: =+F24+F25 | G25: =+G24+G25 | H25: =+H24+H25 | I25: =+I24+I25 | J25: =SUM(C23:I23) | M25: =+J23 | N25: =2051000*70 | O25: =2051000*75
B26: Adquisición de Materiales | C26: =+SUM('Valorización Componentes'!C96:C100) | D26: =+SUM('Valorización Componentes'!D96:D100) | E26: =+SUM('Valorización Componentes'!E96:E100) | F26: =+SUM('Valorización Componentes'!F96:F100) | G26: =+SUM('Valorización Componentes'!G96:G100) | H26: =+SUM('Valorización Componentes'!H96:H100) | I26: =+SUM('Valorización Componentes'!I96:I100) | J26: =SUM(C24:I24)
B27: Logistica | C27: =+SUM('Valorización Componentes'!C102:C106) | D27: =+SUM('Valorización Componentes'!D102:D106) | E27: =+SUM('Valorización Componentes'!E102:E106) | F27: =+SUM('Valorización Componentes'!F102:F106) | G27: =+SUM('Valorización Componentes'!G102:G106) | H27: =+SUM('Valorización Componentes'!H102:H106) | I27: =+SUM('Valorización Componentes'!I102:I106) | J27: =SUM(C25:I25)
A28: 7 | B28: instalacion | C28: =+'Valorización Componentes'!C107 | D28: =+'Valorización Componentes'!D107 | E28: =+'Valorización Componentes'!E107 | F28: =+'Valorización Componentes'!F107 | G28: =+'Valorización Componentes'!G107 | H28: =+'Valorización Componentes'!H107 | I28: =+'Valorización Componentes'!I107 | J28: =SUM(C26:I26) | L28: =+J26
B29: Logistica y Abastecimiento
B30: Instalación de Equipos
B31: Te1
A32: 8 | B32: Formación y Asesoria a usuarios de electrodomésticos y uso. | C32: =+'Valorización Componentes'!C166 | D32: =+'Valorización Componentes'!D166 | E32: =+'Valorización Componentes'!E166 | F32: =+'Valorización Componentes'!F166 | G32: =+'Valorización Componentes'!G166 | H32: =+'Valorización Componentes'!H166 | I32: =+'Valorización Componentes'!I166 | J32: =SUM(C30:I30) | L32: =+J30
B33: Asesoría a usuarios sobre uso eficiente de electrodomésticos, priorización de consumos y prevención de sobrecargas.
B34: Acompañamiento inicial post-instalación para resolver dudas de uso, operación segura y buenas prácticas de consumo.
A35: 9 | B35: Cierre de proyecto - informes de instalación | C35: =+'Valorización Componentes'!C184 | D35: =+'Valorización Componentes'!D184 | E35: =+'Valorización Componentes'!E184 | F35: =+'Valorización Componentes'!F184 | G35: =+'Valorización Componentes'!G184 | H35: =+'Valorización Componentes'!H184 | I35: =+'Valorización Componentes'!I184 | J35: =SUM(C33:I33) | L35: =+J33
B36: Revisión y recopilación de actas de instalación, registros fotográficos, fichas técnicas y respaldos por vivienda.
B37: Elaboración de informes técnicos de instalación y puesta en marcha por sistema o grupo de beneficiarios.
B38: Preparación del informe final de cierre del proyecto, consolidando resultados, cumplimiento de metas y medios de verificación.
B39: TOTAL PROYECTO | C39: =SUM(C4:C33) | D39: =SUM(D4:D33) | E39: =SUM(E4:E33) | F39: =SUM(F4:F33) | G39: =SUM(G4:G33) | H39: =SUM(H4:H33) | I39: =SUM(I4:I33) | J39: =+J4+J8+J12+J16+J20+J22+J23+J26+J30+J33 | K39: =SUM(C37:I37)-J37 | L39: =SUM(L4:L33) | M39: =SUM(M4:M33)
L40: =L37/J37 | M40: =M37/J37
B41: CERRADO
B42: Ítem / Descripción | C42: Ago 2026 | D42: Sep 2026 | E42: Oct 2026 | F42: Nov 2026 | G42: Dic 2026 | H42: Ene 2027 | I42: Feb 2027 | J42: TOTAL | L42: GORE | M42: FUNDACIÓN
...

Sheet Valorización Componentes
A1: VALORIZACIÓN POR COMPONENTE — LUZ EN CASA · GORE COQUIMBO | Valores BRUTO con IVA
J2: =+J202
B3: Ítem / Descripción | C3: Ago 2026 | D3: Sep 2026 | E3: Oct 2026 | F3: Nov 2026 | G3: Dic 2026 | H3: Ene 2027 | I3: Feb 2027 | J3: TOTAL
A4: 1 | B4: Diagnóstico general y catastro básico de hogares en La Higuera | C4: =SUM(C5:C21) | D4: =SUM(D5:D21) | E4: =SUM(E5:E21) | F4: =SUM(F5:F21) | G4: =SUM(G5:G21) | H4: =SUM(H5:H21) | I4: =SUM(I5:I21) | J4: =SUM(C4:I4) | K4: RRCC | L4: 1+2+3
B5: Planilla Actual | C5: =+'Flujo Bruto'!O21
B6: Descarga estructura | C6: =+'Flujo Bruto'!O22
B7: Encargado territorial RRHH | C7: =+'Flujo Bruto'!O29
B8: Arriendo vehículo diario - RRCC | C8: =+'Flujo Bruto'!O34
B9: Vehiculo RRCC | C9: =+'Flujo Bruto'!O30
B10: Traslados de personal | C10: =+'Flujo Bruto'!O50
B11: Alojamiento | C11: =+'Flujo Bruto'!O51
B12: Alimentación | C12: =+'Flujo Bruto'!O52
B13: Combustible arriendo diario | C13: =+'Flujo Bruto'!O53
B14: Combustible arriendo mensual | C14: =+'Flujo Bruto'!O54
B15: Peajes | C15: =+'Flujo Bruto'!O55
B16: Compras de Equipos, EEPP, Otros | C16: =+'Flujo Bruto'!O64
B17: Mensajerias (Correo de Chile) | C17: =+'Flujo Bruto'!O65
B18: Impresión de manuales | C18: =+'Flujo Bruto'!O66
B19: Mantención y reparación de Vehículos | C19: =+'Flujo Bruto'!O67
B20: Otros varios | C20: =+'Flujo Bruto'!O68
A22: 2 | B22: Catastro georeferenciado uno a uno de viviendas | C22: =SUM(C23:C39) | D22: =SUM(D23:D39) | E22: =SUM(E23:E39) | F22: =SUM(F23:F39) | G22: =SUM(G23:G39) | H22: =SUM(H23:H39) | I22: =SUM(I23:I39) | J22: =SUM(C22:I22) | K22: RRCC | L22: 1+2+3
B23: Planilla Actual | D23: 2400000
B24: Descarga estructura
B25: Encargado territorial RRHH | D25: 900000
B26: Arriendo vehículo diario - RRCC | D26: =Supuestos!G37*15
B27: Vehiculo RRCC
B28: Traslados de personal
B29: Alojamiento | D29: 1500000
B30: Alimentación | D30: 1500000
B31: Combustible arriendo diario | D31: 1000000
B32: Combustible arriendo mensual
B33: Peajes | D33: 400000
B34: Compras de Equipos, EEPP, Otros | D34: 1200000
B35: Mensajerias (Correo de Chile)
B36: Impresión de manuales
B37: Mantención y reparación de Vehículos
B38: Otros varios
A40: 3 | B40: Verificación y sensibilización de usuarios catastrados. Incorporación de beneficiarios a programa de energía. | C40: =SUM(C41:C57) | D40: =SUM(D41:D57) | E40: =SUM(E41:E57) | F40: =SUM(F41:F57) | G40: =SUM(G41:G57) | H40: =SUM(H41:H57) | I40: =SUM(I41:I57) | J40: =SUM(C40:I40) | K40: RRCC | L40: 1+2+3
B41: Planilla Actual
B42: Descarga estructura | E42: 8000000
...

Sheet Carátula
A1: CARÁTULA — LUZ EN CASA · GORE COQUIMBO
A3: LUZ EN CASA · GORE COQUIMBO
A4: Fundación acciona.org · Financiamiento FNDR · 75 sistemas FV domiciliarios
B6: Proyecto | D6: Luz en Casa — Electrificación rural fotovoltaica
B7: Financiador | D7: Gobierno Regional de Coquimbo (GORE) — FNDR Subt. 33
B8: Ejecutor | D8: Fundación acciona.org
B9: Responsable | D9: Agustín Delgado Godoy — Project Manager
B10: N° equipos | D10: 75 sistemas SHS AC (Zimpertec GmbH, Alemania)
B11: Período ejecución | D11: Julio 2026 – Febrero 2027 (instalaciones)
B12: Cierre administrativo | D12: Junio 2027
B13: Aporte GORE | D13: $170.000.000 CLP (tope convenio)
B14: Total proyecto NETO | D14: $278.551.000 CLP
B15: Total proyecto BRUTO | D15: $338.684.840 CLP (con IVA 19%)
A18: ÍNDICE DE PESTAÑAS — Haz clic en el nombre para ir directamente
B20: Pestaña (clic para ir) | C20: Categoría | D20: Descripción y contenido | E20: Notas / Responsable
B21: → Supuestos | C21: Modelo financiero | D21: Parámetros base del modelo: cantidad de equipos (75), tasa de cambio USD/CLP, precios unitarios, factores de distribución mensual (0.3 / 0.5 / 0.2). Celda de control central del modelo. | E21: Edición: Agustín D.
B22: → Flujo Neto | C22: Modelo financiero | D22: Presupuesto mensual en valores NETO (sin IVA). 10 grupos de gasto (ítems 1–10), distribución mes a mes Ago 2026–Feb 2027. Total NETO: $278.551.000. Fuente de Analítica y General GORE. | E22: Solo lectura — fórmulas vinculadas a Supuestos
B23: → Flujo Bruto | C23: Modelo financiero | D23: Presupuesto mensual en valores BRUTO (con IVA 19%). Misma estructura que Flujo Neto. Total BRUTO: $338.684.840. Fuente de Cashflow y General GORE. | E23: Solo lectura — fórmulas vinculadas a Supuestos
B24: → General GORE | C24: Modelo financiero | D24: Resumen ejecutivo del proyecto para presentación GORE. Cuadro de fuentes y usos, aporte FNDR vs Fundación, total por partida presupuestaria. | E24: Agustín D. / GORE
B25: → Carta Gantt | C25: Planificación | D25: Cronograma de 9 fases (jul 2026–jun 2027): gestión, compra, importación, contratación, materiales, logística, instalación (75 uds en 3 lotes), rendición y cierre. 42 actividades y 5 hitos. | E25: v1.5 — Actualizar al firmar convenio
B26: → Antecedentes Programa | C26: Contexto | D26: Descripción del programa Luz en Casa: historia, piloto 2021, expansión regional, forma de trabajo, descripción técnica de equipos SHS AC, alcance de instalación y proceso formal TE-1. | E26: Referencia — no editar
B27: → Planilla SISREC | C27: Rendición | D27: Plantilla mensual de rendición electrónica (SISREC). Una fila por documento (factura / boleta / BH). Campos: N° doc, RUT proveedor, glosa, analítica, tipo doc, montos NETO/IVA/BRUTO, estado. | E27: Apoyo Financiero — completar mensualmente
B28: → Rendición GORE | C28: Rendición | D28: Formato de informe de rendición hacia GORE Coquimbo. Carta conductora, conciliación bancaria, cuadro de gastos acumulados vs cuota. | E28: Apoyo Financiero / Agustín D.
B29: → Tabla Calculo Sueldo | C29: Auxiliar | D29: Tabla auxiliar de costo empresa para personal en planilla. Cotizaciones previsionales, AFP, salud, seguro cesantía. Alimenta ítem 3.1 Planilla Actual del Flujo Neto. | E29: Referencia — no editar directamente
B30: → Guía Maestra | C30: Diagnóstico | D30: Mapa completo del modelo: pestañas, roles, editabilidad, dependencias. Tabla ítem a código analítica a cashflow. Control de totales y reglas de edición. | E30: Lectura obligatoria antes de editar
B31: → Diagnóstico Vínculos | C31: Diagnóstico | D31: Auditoría de vínculos rotos entre pestañas. Lista de celdas con errores, causa y acción correctiva. | E31: Actualizar en cada versión
... B33: → Cashflow | C33: Auxiliar | D33: Cashflow mensual del proyecto. Cobros y pagos por categoría. Vinculado a Flujo Bruto. Columna de desviación inactiva hasta ingresar valores de Budget. | E33: Sistema ACCIONA — no editar
A36: CONTROL DE REVISIONES
B38: Versión | C38: Fecha | D38: Autor | E38: Descripción del cambio
B39: v1.0 | C39: 17/02/2026 | D39: Agustín D. | E39: Versión inicial. Supuestos, Flujo Neto, Flujo Bruto, General GORE. 60 equipos. TC USD 950.
B40: v1.1 | C40: Feb 2026 | D40: Agustín D. | E40: Incorporación Analítica y Cashflow del sistema ACCIONA. Vínculos con Flujo Bruto.
B41: v1.2 | C41: Mar 2026 | D41: Agustín D. | E41: Tabla Calculo Sueldo. Ajuste planilla personal. Revisión ítems 3. y 4.
B42: v1.3 | C42: Abr 2026 | D42: Agustín D. | E42: Incorporación Planilla SISREC, Rendición GORE, Diagnóstico Vínculos, Guía Maestra.
B43: v1.4 | C43: 13/05/2026 | D43: Agustín D. | E43: Ajuste a 75 equipos. TC USD 1.000. Actualización Flujo Neto/Bruto. Carta Gantt ene 2026–jun 2027 (referencial).
B44: v1.5 | C44: 13/05/2026 | D44: Agustín D. | E44: Carta Gantt reconstruida: inicio jul 2026, fin instalaciones feb 2027, 9 fases, 42 actividades, 5 hitos.
B45: v1.6 | C45: 14/05/2026 | D45: Agustín D. | E45: Carátula con índice de pestañas, hyperlinks, control de revisiones y registro de mejoras.
B46: v2.0 | C46: 14/05/2026 | D46: Agustín D. | E46: Carátula rediseñada: hyperlinks corregidos, Total BRUTO agregado, RUT y nombre de archivo eliminados, versión migrada a 2.0.
B47: v2.1 | C47: __/__/____ | D47: ____________ | E47: Completar al publicar próxima versión
A50: REGISTRO DE MEJORAS PENDIENTES
B52: ID | C52: Prioridad | D52: Descripción de la mejora | E52: Estado
...

Sheet General GORE
A1: RESUMEN GENERAL — PROYECTO LUZ EN CASA · GORE COQUIMBO
A2: Fundación acciona.org (Grupo ACCIONA) · Financiamiento FNDR Subtítulo 33 · Región de Coquimbo
A3: 1. EQUIPOS SUMINISTRADOS — ZIMPERTEC GmbH & Co. KG (Alemania)
B4: Componente | C4: Modelo | D4: Especificación principal | E4: Qty por kit | F4: Total proyecto (60 kits) | G4: Observaciones
B5: Sistema Solar Domiciliario AC (SHS AC) | C5: AC-LS-AC25.6V/50Ah/ 1.28kWh/220V/50Hz/ 0.9kW-HP/Termcon-a | D5: Inversor 900W · Batería LFP 25.6V/50Ah/1.28kWh · Controlador PWM 40A · Salida DC 24V/10A · Gabinete gris acciona.org | E5: 1 | F5: 60 | G5: Gabinete especial para acciona.org · optimizado para cargas AC básicas y picos de motor
B6: Panel solar fotovoltaico | C6: SP-500-66M-S4-0.35 | D6: 500 Wp · Monocristalino · 66 celdas en serie · Cableado S4 terminal 0.35 m | E6: 2 | F6: 120 | G6: 2 paneles por kit · orientación optimizada en cubierta
B7: Luminaria LED | C7: SFL-12-24/05CW | D7: 5W · 12/24 VDC · Cool White · Cert. CE y ROHS | E7: 3 | F7: 180 | G7: 3 puntos iluminación DC por vivienda · máx. 20 m cableado interior
B8: Alcance instalación por vivienda: 3 luminarias LED DC (12/24V) + 1 toma corriente AC (220V/50Hz) · máx 20 m cableado · TE-1 voluntaria SEC · Acta recepción conforme
A9: 2. SUPUESTOS FINANCIEROS — COSTO UNITARIO POR INSTALACIÓN
B10: Concepto | C10: Valor NETO (CLP) | D10: Valor BRUTO (CLP) | E10: Referencia Supuestos | F10: Notas
B11: Costo equipos + traslados asociados (GORE) | D11: =Supuestos!F74 | E11: Supuestos!F71 | F11: Sistemas AC + Paneles + Lámparas + Flete + Transp.descons. + Grúas
B12: Costo personal, logística, materiales, vehículos, viajes | C12: =Supuestos!I4 | D12: =Supuestos!F75 | E12: Supuestos!F72 | F12: Calculado como: K5 (unitario resto de ítems)
B13: TOTAL COSTO UNITARIO (NETO) | C13: ='Flujo Neto'!AJ69/'General GORE'!C27 | E13: Supuestos!I5 | F13: Suma unitaria NETO
B14: TOTAL COSTO UNITARIO (BRUTO) | D14: =C20/'General GORE'!C27 | E14: Flujo Bruto!AJ68 | F14: Unitario BRUTO = total proyecto / 60 equipos
A15: 3. VALIDADOR FINANCIERO — TOPE MÁXIMO GORE $170.000.000 (50% del proyecto)
B16: Concepto | C16: Valor CLP | D16: % del Total Bruto | E16: Estado | F16: Referencia / Fórmula
B17: Aporte GORE (tope máximo reembolsable) | C17: 170000000 | D17: =C17/'Flujo Bruto'!AJ69 | E17: =IF(C17<='Flujo Bruto'!AJ69,"✓ GORE ≤ Total proyecto","⚠ GORE > Total proyecto") | F17: Hardcoded · ref. Rodrigo Soto
B18: Aporte Fundación acciona.org (50% complementario) | C18: 170000000 | D18: =C18/'Flujo Bruto'!AJ69 | E18: =IF(C17=C18,"✓ Aporte simétrico","⚠ Aportes asimétricos") | F18: Hardcoded · $170MM = $170MM
B19: Total comprometido (GORE + Fundación) | C19: =C17+C18 | D19: =C19/C19 | E19: ✓ $340.000.000 total | F19: C17 + C18
B20: Costo total real del proyecto (Flujo Bruto) | C20: ='Flujo Bruto'!AJ69 | D20: ='Flujo Bruto'!AJ69/C19 | E20: =IF('Flujo Bruto'!AJ69<=C19,"✓ Dentro del tope","⚠ EXCEDE tope $340MM") | F20: Flujo Bruto!AJ66 (total 60 equipos) | G20: =+C20-C19
B21: Costo unitario real BRUTO (por instalación) | C21: =D14 | D21: =C21/(C19/C27) | E21: =IF(C21<=C19/60,"✓ Dentro del tope unit.","⚠ Supera tope unitario")
B22: Costo equipos+traslados GORE (K3 × 60 equipos) | C22: =Supuestos!F74*Supuestos!E2 | D22: =C22/'Flujo Bruto'!AJ69 | E22: =IF(C22<=C17,"✓ Equip. dentro aporte GORE","⚠ Equip. supera aporte") | F22: K3 × E2 (Supuestos)
B23: Saldo GORE disponible para otros ítems (GORE - equip.) | C23: =C17-C22 | D23: =C23/C17 | E23: =IF(C23>=0,"✓ GORE cubre equipos","⚠ GORE insuficiente para equipos") | F23: C17 - C22
A24: ⚠ VALIDACIÓN: Los valores en amarillo se calculan desde Flujo Bruto (dinámicos). Los valores en verde ya cumplen la condición. Si algún estado dice "⚠", revisar Supuestos antes de presentar al GORE.
A25: 4. PARÁMETROS CLAVE DEL PROYECTO
B26: Parámetro | C26: Valor actual | D26: Fuente | E26: Editar en | F26: Notas
B27: N° equipos a comprar | C27: =Supuestos!E2 | D27: Supuestos!E2 | E27: Supuestos!E2 | F27: Cantidad de kits FV completos
B28: Tasa de cambio USD/CLP | C28: =Supuestos!E3 | D28: Supuestos!E3 | E28: Supuestos!E3 | F28: Solo para referencia en Supuestos
B29: N° cuadrillas de instalación | C29: =Supuestos!E4 | D29: Supuestos!E4 | E29: Supuestos!E4 | F29: Afecta herramientas (ítem 2.3)
B30: Costo unitario equipos GORE (K3) | C30: =Supuestos!F74 | D30: Supuestos!K3 | E30: ⛔ Calculado | F30: Fórmula: K4 + (K43+K46+K47)/E2
B31: Tiempo importación (meses) | C31: 4-5 meses | D31: Minuta Proyecto | E31: —
B32: Modelo pago usuarios | C32: Caja Vecina BancoEstado | D32: Minuta Proyecto | E32: — | F32: ~30.000 sucursales acceso rural
B33: Cantidad de equipos financiables (C11/C12) | C33: =C17/Supuestos!F74 | D33: Calculado | E33: — | F33: GORE $170MM ÷ K3 unitario
B34: Cantidad de equipos finales | C34: 75 | D34: Supuestos | E34: — | F34: [VERIFICAR] ajustar según convenio
B35: Costo total compra (75 × K3) | C35: =75*Supuestos!F74 | D35: Calculado | E35: — | F35: 75 equipos × K3 unitario
A37: ℹ Para antecedentes y contexto del programa, ver pestaña → Antecedentes Programa

Sheet AUMENTO MONTO
A1: AUMENTO DE MONTO — Fuente Oficial · Actualizado 5 de Junio 2026
A2: Luz en Casa · GORE Coquimbo · Fundación acciona.org
B4: MONTO | C4: Unidad
A5: TOTAL COSTO UNITARIO (BRUTO) | B5: 4625776.3 | C5: CLP
A6: CANTIDAD INSTALACIONES | B6: 75 | C6: UN
A7: COSTO PROYECTO | B7: =PRODUCT(B3:B4) | C7: CLP
A9: TOTAL COSTO UNITARIO (BRUTO) | B9: 4267000 | C9: CLP | D9: <----- | E9: VALOR AJUSTADO EN PESTAÑA GORE
A10: CANTIDAD INSTALACIONES | B10: 75 | C10: UN
A11: COSTO PROYECTO | B11: =PRODUCT(B7:B8) | C11: CLP
A13: NUEVA PROPUESTA
A14: GORE | B14: 280000000 | C14: CLP
A15: FUNDACIÓN ACCIONA | B15: 280000000 | C15: CLP
A16: TOTAL | B16: =SUM(B12:B13) | C16: CLP
A18: TOTAL COSTO UNITARIO (BRUTO) | B18: =+B7 | C18: CLP
A19: Cantidad Instalaciones | B19: =B14/B16 | C19: UN
A21: Cantidad Extra | B21: =B8-B17

Sheet Flujo Bruto
A1: FLUJO BRUTO (PRECIOS BRUTO CON IVA) — LUZ EN CASA · GORE COQUIMBO
D4: PRECIOS BRUTO | P4: Voluntariado | Q4: Voluntariado | R4: Voluntariado
B5: Forma pago | C5: Nivel | D5: Item | H5: 46023 | I5: 46054 | J5: 46082 | K5: 46113 | L5: 46143 | M5: 46174 | N5: 46204 | O5: 46235 | P5: 46266 | Q5: 46296 | R5: 46327 | S5: 46357 | T5: 2026 | V5: 46388 | W5: 46419 | X5: 46447 | Y5: 46478 | Z5: 46508 | AA5: 46539 | AB5: 46569 | AC5: 46600 | AD5: 46631 | AE5: 46661 | AF5: 46692 | AG5: 46722 | AH5: 2026 | AJ5: TOTAL
C6: 1 | D6: Compras activables ZIMPERTEC | E6: =+Supuestos!E8 | F6: =+F76 | H6: =+SUM(H6:H15) | I6: =+SUM(I6:I15) | J6: =+SUM(J6:J15) | K6: =+SUM(K6:K15) | L6: =+SUM(L6:L15) | M6: =+SUM(M6:M15) | N6: =+SUM(N6:N15) | O6: =+SUM(O6:O15) | ... S6: =+SUM(S6:S15) | T6: =SUM(H5:S5) | V6: =+SUM(V6:V15) | W6: =+SUM(W6:W15) | X6: =+SUM(X6:X15) | Y6: =+SUM(Y6:Y15) | Z6: =+SUM(Z6:Z15) | AA6: =+SUM(AA6:AA15) | AB6: =+SUM(AB6:AB15) | AC6: =+SUM(AC6:AC15) | ... AG6: =+SUM(AG6:AG15) | AH6: =SUM(V5:AG5) | AJ6: =+AH5+T5
B7: Factura | C7: 1.1 | D7: Sistemas AC | E7: =+Supuestos!G9 | F7: =+F77 | H7: =+$E6*H77 | I7: =+$E6*I77 | J7: =+$E6*J77 | K7: =+$E6*K77 | L7: =+$E6*L77 | M7: =+$E6*M77 | N7: =+$E6*N77 | O7: =+$E6*O77 | ... S7: =+$E6*S77 | T7: =SUM(H6:S6) | V7: =+$E6*V77 | W7: =+$E6*W77 | X7: =+$E6*X77 | Y7: =+$E6*Y77 | Z7: =+$E6*Z77 | AA7: =+$E6*AA77 | AB7: =+$E6*AB77 | AC7: =+$E6*AC77 | ... AG7: =+$E6*AG77 | AH7: =SUM(V6:AG6) | AJ7: =+AH6+T6
B8: Factura | C8: 1.2 | D8: Paneles | E8: =+Supuestos!G10 | F8: =+F78 | H8: =+$E7*H78 | I8: =+$E7*I78 | J8: =+$E7*J78 | K8: =+$E7*K78 | L8: =+$E7*L78 | M8: =+$E7*M78 | N8: =+$E7*N78 | O8: =+$E7*O78 | ... S8: =+$E7*S78 | T8: =SUM(H7:S7) | V8: =+$E7*V78 | W8: =+$E7*W78 | X8: =+$E7*X78 | Y8: =+$E7*Y78 | Z8: =+$E7*Z78 | AA8: =+$E7*AA78 | AB8: =+$E7*AB78 | AC8: =+$E7*AC78 | ... AG8: =+$E7*AG78 | AH8: =SUM(V7:AG7) | AJ8: =+AH7+T7
B9: Factura | C9: 1.3 | D9: Lamparas | E9: =+Supuestos!G11 | F9: =+F79 | H9: =+$E8*H79 | I9: =+$E8*I79 | J9: =+$E8*J79 | K9: =+$E8*K79 | L9: =+$E8*L79 | M9: =+$E8*M79 | N9: =+$E8*N79 | O9: =+$E8*O79 | ... S9: =+$E8*S79 | T9: =SUM(H8:S8) | V9: =+$E8*V79 | W9: =+$E8*W79 | X9: =+$E8*X79 | Y9: =+$E8*Y79 | Z9: =+$E8*Z79 | AA9: =+$E8*AA79 | AB9: =+$E8*AB79 | AC9: =+$E8*AC79 | ... AG9: =+$E8*AG79 | AH9: =SUM(V8:AG8) | AJ9: =+AH8+T8
B10: Factura | C10: 1.4 | D10: Hardware Monitoreo | E10: =+Supuestos!G12 | F10: =+F80 | H10: =+$E9*H80 | I10: =+$E9*I80 | J10: =+$E9*J80 | K10: =+$E9*K80 | L10: =+$E9*L80 | M10: =+$E9*M80 | N10: =+$E9*N80 | O10: =+$E9*O80 | ... S10: =+$E9*S80 | T10: =SUM(H9:S9) | V10: =+$E9*V80 | W10: =+$E9*W80 | X10: =+$E9*X80 | Y10: =+$E9*Y80 | Z10: =+$E9*Z80 | AA10: =+$E9*AA80 | AB10: =+$E9*AB80 | AC10: =+$E9*AC80 | ... AG10: =+$E9*AG80 | AH10: =SUM(V9:AG9) | AJ10: =+AH9+T9
B11: Factura | C11: 1.5 | D11: Software Monitoreo | E11: =+Supuestos!G13 | F11: =+F81 | H11: =+$E10*H81 | I11: =+$E10*I81 | J11: =+$E10*J81 | K11: =+$E10*K81 | L11: =+$E10*L81 | M11: =+$E10*M81 | N11: =+$E10*N81 | O11: =+$E10*O81 | ... S11: =+$E10*S81 | V11: =+$E10*V81 | W11: =+$E10*W81 | X11: =+$E10*X81 | Y11: =+$E10*Y81 | Z11: =+$E10*Z81 | AA11: =+$E10*AA81 | AB11: =+$E10*AB81 | AC11: =+$E10*AC81 | ... AG11: =+$E10*AG81 | AJ11: =+AH10+T10
B12: Factura | C12: 1.6 | D12: Repuestos | E12: =+Supuestos!G14 | F12: =+F82 | H12: =+$E11*H82 | I12: =+$E11*I82 | J12: =+$E11*J82 | K12: =+$E11*K82 | L12: =+$E11*L82 | M12: =+$E11*M82 | N12: =+$E11*N82 | O12: =+$E11*O82 | ... S12: =+$E11*S82 | T12: =SUM(H11:S11) | V12: =+$E11*V82 | W12: =+$E11*W82 | X12: =+$E11*X82 | Y12: =+$E11*Y82 | Z12: =+$E11*Z82 | AA12: =+$E11*AA82 | AB12: =+$E11*AB82 | AC12: =+$E11*AC82 | ... AG12: =+$E11*AG82 | AH12: =SUM(V11:AG11) | AJ12: =+AH11+T11
B13: Factura | C13: 1.7 | D13: Flete | E13: =+Supuestos!G15 | F13: =+F83 | H13: =+$E12*H83 | I13: =+$E12*I83 | J13: =+$E12*J83 | K13: =+$E12*K83 | L13: =+$E12*L83 | M13: =+$E12*M83 | N13: =+$E12*N83 | O13: =+$E12*O83 | ... S13: =+$E12*S83 | T13: =SUM(H12:S12) | V13: =+$E12*V83 | W13: =+$E12*W83 | X13: =+$E12*X83 | Y13: =+$E12*Y83 | Z13: =+$E12*Z83 | AA13: =+$E12*AA83 | AB13: =+$E12*AB83 | AC13: =+$E12*AC83 | ... AG13: =+$E12*AG83 | AH13: =SUM(V12:AG12) | AJ13: =+AH12+T12
B14: Factura | C14: 7.2 | D14: Transporte DESCONSOLIDADO | E14: =+Supuestos!G16 | F14: =+F84 | H14: =+$E13*H84 | I14: =+$E13*I84 | J14: =+$E13*J84 | K14: =+$E13*K84 | L14: =+$E13*L84 | M14: =+$E13*M84 | N14: =+$E13*N84 | O14: =+$E13*O84 | ... S14: =+$E13*S84 | T14: =SUM(H13:S13) | V14: =+$E13*V84 | W14: =+$E13*W84 | X14: =+$E13*X84 | Y14: =+$E13*Y84 | Z14: =+$E13*Z84 | AA14: =+$E13*AA84 | AB14: =+$E13*AB84 | AC14: =+$E13*AC84 | ... AG14: =+$E13*AG84 | AH14: =SUM(V13:AG13) | AJ14: =+AH13+T13
B15: Factura | C15: 7.5 | D15: Grúa en Origen | E15: =+Supuestos!G17 | F15: =+F85 | H15: =+$E14*H85 | I15: =+$E14*I85 | J15: =+$E14*J85 | K15: =+$E14*K85 | L15: =+$E14*L85 | M15: =+$E14*M85 | N15: =+$E14*N85 | O15: =+$E14*O85 | ... S15: =+$E14*S85 | T15: =SUM(H14:S14) | V15: =+$E14*V85 | W15: =+$E14*W85 | X15: =+$E14*X85 | Y15: =+$E14*Y85 | Z15: =+$E14*Z85 | AA15: =+$E14*AA85 | AB15: =+$E14*AB85 | AC15: =+$E14*AC85 | ... AG15: =+$E14*AG85 | AH15: =SUM(V14:AG14) | AJ15: =+AH14+T14
B16: Factura | C16: 7.6 | D16: Grúa en Punto Destino (6 Horas) | E16: =+Supuestos!G18 | F16: =+F86 | H16: =+$E15*H86 | I16: =+$E15*I86 | J16: =+$E15*J86 | K16: =+$E15*K86 | L16: =+$E15*L86 | M16: =+$E15*M86 | N16: =+$E15*N86 | O16: =+$E15*O86 | ... S16: =+$E15*S86 | T16: =SUM(H15:S15) | V16: =+$E15*V86 | W16: =+$E15*W86 | X16: =+$E15*X86 | Y16: =+$E15*Y86 | Z16: =+$E15*Z86 | AA16: =+$E15*AA86 | AB16: =+$E15*AB86 | AC16: =+$E15*AC86 | ... AG16: =+$E15*AG86 | AH16: =SUM(V15:AG15) | AJ16: =+AH15+T15
C17: 2 | D17: Insumos Instalación | E17: =+Supuestos!E19 | F17: =+F87 | H17: =+SUM(H17:H19) | I17: =+SUM(I17:I19) | J17: =+SUM(J17:J19) | K17: =+SUM(K17:K19) | L17: =+SUM(L17:L19) | M17: =+SUM(M17:M19) | N17: =+SUM(N17:N19) | O17: =+SUM(O17:O19) | ... S17: =+SUM(S17:S19) | T17: =SUM(H16:S16) | V17: =+SUM(V17:V19) | W17: =+SUM(W17:W19) | X17: =+SUM(X17:X19) | Y17: =+SUM(Y17:Y19) | Z17: =+SUM(Z17:Z19) | AA17: =+SUM(AA17:AA19) | AB17: =+SUM(AB17:AB19) | AC17: =+SUM(AC17:AC19) | ... AG17: =+SUM(AG17:AG19) | AH17: =SUM(V16:AG16) | AJ17: =+AH16+T16
B18: Factura | C18: 2.1 | D18: Estructura | E18: =+Supuestos!G20 | F18: =+F88 | H18: =+$E17*H88 | I18: =+$E17*I88 | J18: =+$E17*J88 | K18: =+$E17*K88 | L18: =+$E17*L88 | M18: =+$E17*M88 | N18: =+$E17*N88 | O18: =+$E17*O88 | ... S18: =+$E17*S88 | T18: =SUM(H17:S17) | V18: =+$E17*V88 | W18: =+$E17*W88 | X18: =+$E17*X88 | Y18: =+$E17*Y88 | Z18: =+$E17*Z88 | AA18: =+$E17*AA88 | AB18: =+$E17*AB88 | AC18: =+$E17*AC88 | ... AG18: =+$E17*AG88 | AH18: =SUM(V17:AG17) | AJ18: =+AH17+T17
B19: Factura o Boleta | C19: 2.2 | D19: Materiales instalación | E19: =+Supuestos!G21 | F19: =+F89 | H19: =+$E18*H89 | I19: =+$E18*I89 | J19: =+$E18*J89 | K19: =+$E18*K89 | L19: =+$E18*L89 | M19: =+$E18*M89 | N19: =+$E18*N89 | O19: =+$E18*O89 | ... S19: =+$E18*S89 | T19: =SUM(H18:S18) | V19: =+$E18*V89 | W19: =+$E18*W89 | X19: =+$E18*X89 | Y19: =+$E18*Y89 | Z19: =+$E18*Z89 | AA19: =+$E18*AA89 | AB19: =+$E18*AB89 | AC19: =+$E18*AC89 | ... AG19: =+$E18*AG89 | AH19: =SUM(V18:AG18) | AJ19: =+AH18+T18
B20: Factura o Boleta | C20: 2.3 | D20: Herramientas | E20: =+Supuestos!G22 | F20: =+F90 | H20: =+$E19*H90 | I20: =+$E19*I90 | J20: =+$E19*J90 | K20: =+$E19*K90 | L20: =+$E19*L90 | M20: =+$E19*M90 | N20: =+$E19*N90 | O20: =+$E19*O90 | ... S20: =+$E19*S90 | T20: =SUM(H19:S19) | V20: =+$E19*V90 | W20: =+$E19*W90 | X20: =+$E19*X90 | Y20: =+$E19*Y90 | Z20: =+$E19*Z90 | AA20: =+$E19*AA90 | AB20: =+$E19*AB90 | AC20: =+$E19*AC90 | ... AG20: =+$E19*AG90 | AH20: =SUM(V19:AG19) | AJ20: =+AH19+T19
C21: 3. | D21: Personal y Servicios | E21: =+Supuestos!E23 | F21: =+F91 | H21: =+H21+H22 | I21: =+I21+I22 | J21: =+J21+J22 | K21: =+K21+K22 | L21: =+L21+L22 | M21: =+M21+M22 | N21: =+N21+N22 | O21: =+O21+O22 | ... S21: =+S21+S22 | T21: =SUM(H20:S20) | V21: =+V21+V22 | W21: =+W21+W22 | X21: =+X21+X22 | Y21: =+Y21+Y22 | Z21: =+Z21+Z22 | AA21: =+AA21+AA22 | AB21: =+AB21+AB22 | AC21: =+AC21+AC22 | ... AG21: =+AG21+AG22 | AH21: =SUM(V20:AG20) | AJ21: =+AH20+T20
B22: Costo Empresa | C22: 3.1 | D22: Planilla Actual | E22: =+Supuestos!E24 | F22: =+F92 | H22: =+$E21*H92 | I22: =+$E21*I92 | J22: =+$E21*J92 | K22: =+$E21*K92 | L22: =+$E21*L92 | M22: =+$E21*M92 | N22: =+$E21*N92 | O22: =+$E21*O92 | ... S22: =+$E21*S92 | T22: =SUM(H21:S21) | V22: =+$E21*V92 | W22: =+$E21*W92 | X22: =+$E21*X92 | Y22: =+$E21*Y92 | Z22: =+$E21*Z92 | AA22: =+$E21*AA92 | AB22: =+$E21*AB92 | AC22: =+$E21*AC92 | ... AG22: =+$E21*AG92 | AH22: =SUM(V21:AG21) | AJ22: =+AH21+T21
C23: 3.2 | D23: Descarga estructura | E23: =+Supuestos!E25 | H23: =+$E22*H93 | I23: =+$E22*I93 | J23: =+$E22*J93 | K23: =+$E22*K93 | L23: =+$E22*L93 | M23: =+$E22*M93 | N23: =+$E22*N93 | O23: =+$E22*O93 | ... S23: =+$E22*S93 | T23: =SUM(H22:S22) | V23: =+$E22*V93 | W23: =+$E22*W93 | X23: =+$E22*X93 | Y23: =+$E22*Y93 | Z23: =+$E22*Z93 | AA23: =+$E22*AA93 | AB23: =+$E22*AB93 | AC23: =+$E22*AC93 | ... AG23: =+$E22*AG93 | AH23: =SUM(V22:AG22) | AJ23: =+AH22+T22
C24: 4. | D24: Servicios Profesionales | E24: =+Supuestos!E26 | F24: =+F94 | H24: =+SUM(H24:H31) | I24: =+SUM(I24:I31) | J24: =+SUM(J24:J31) | K24: =+SUM(K24:K31) | L24: =+SUM(L24:L31) | M24: =+SUM(M24:M31) | N24: =+SUM(N24:N31) | O24: =+SUM(O24:O31) | ... S24: =+SUM(S24:S31) | T24: =SUM(H23:S23) | V24: =+SUM(V24:V31) | W24: =+SUM(W24:W31) | X24: =+SUM(X24:X31) | Y24: =+SUM(Y24:Y31) | Z24: =+SUM(Z24:Z31) | AA24: =+SUM(AA24:AA31) | AB24: =+SUM(AB24:AB31) | AC24: =+SUM(AC24:AC31) | ... AG24: =+SUM(AG24:AG31) | AH24: =SUM(V23:AG23) | AJ24: =+AH23+T23
B25: Boleta Honorarios | C25: 4.1 | D25: Encargado de Logistica y Bodega | E25: =+Supuestos!E27 | F25: =+F95 | H25: =+$E24*H95 | I25: =+$E24*I95 | J25: =+$E24*J95 | K25: =+$E24*K95 | L25: =+$E24*L95 | M25: =+$E24*M95 | N25: =+$E24*N95 | O25: =+$E24*O95 | ... S25: =+$E24*S95 | T25: =SUM(H24:S24) | V25: =+$E24*V95 | W25: =+$E24*W95 | X25: =+$E24*X95 | Y25: =+$E24*Y95 | Z25: =+$E24*Z95 | AA25: =+$E24*AA95 | AB25: =+$E24*AB95 | AC25: =+$E24*AC95 | ... AG25: =+$E24*AG95 | AH25: =SUM(V24:AG24) | AJ25: =+AH24+T24
B26: Boleta Honorarios | C26: 4.2 | D26: Técnico pago por instalación - Plan A | E26: =+Supuestos!E28 | F26: =+F96 | H26: =+$E25*H96 | I26: =+$E25*I96 | J26: =+$E25*J96 | K26: =+$E25*K96 | L26: =+$E25*L96 | M26: =+$E25*M96 | N26: =+$E25*N96 | O26: =+$E25*O96 | ... S26: =+$E25*S96 | T26: =SUM(H25:S25) | V26: =+$E25*V96 | W26: =+$E25*W96 | X26: =+$E25*X96 | Y26: =+$E25*Y96 | Z26: =+$E25*Z96 | AA26: =+$E25*AA96 | AB26: =+$E25*AB96 | AC26: =+$E25*AC96 | ... AG26: =+$E25*AG96 | AH26: =SUM(V25:AG25) | AJ26: =+AH25+T25
B27: Boleta Honorarios | C27: 4.3 | D27: Técnico contrato mensual - Plan B | E27: =+Supuestos!E29 | F27: =+F97 | H27: =+$E26*H97 | I27: =+$E26*I97 | J27: =+$E26*J97 | K27: =+$E26*K97 | L27: =+$E26*L97 | M27: =+$E26*M97 | N27: =+$E26*N97 | O27: =+$E26*O97 | ... S27: =+$E26*S97 | T27: =SUM(H26:S26) | V27: =+$E26*V97 | W27: =+$E26*W97 | X27: =+$E26*X97 | Y27: =+$E26*Y97 | Z27: =+$E26*Z97 | AA27: =+$E26*AA97 | AB27: =+$E26*AB97 | AC27: =+$E26*AC97 | ... AG27: =+$E26*AG97 | AH27: =SUM(V26:AG26) | AJ27: =+AH26+T26
B28: Boleta Honorarios | C28: 4.4 | D28: Ayudante contrato mensual - Plan B | E28: =+Supuestos!E30 | F28: =+F98 | H28: =+$E27*H98 | I28: =+$E27*I98 | J28: =+$E27*J98 | K28: =+$E27*K98 | L28: =+$E27*L98 | M28: =+$E27*M98 | N28: =+$E27*N98 | O28: =+$E27*O98 | ... S28: =+$E27*S98 | T28: =SUM(H27:S27) | V28: =+$E27*V98 | W28: =+$E27*W98 | X28: =+$E27*X98 | Y28: =+$E27*Y98 | Z28: =+$E27*Z98 | AA28: =+$E27*AA98 | AB28: =+$E27*AB98 | AC28: =+$E27*AC98 | ... AG28: =+$E27*AG98 | AH28: =SUM(V27:AG27) | AJ28: =+AH27+T27
B29: Boleta Honorarios | C29: 4.5 | D29: Personal apoyo Planos TE1 | E29: =+Supuestos!E31 | F29: =+F99 | H29: =+$E28*H99 | I29: =+$E28*I99 | J29: =+$E28*J99 | K29: =+$E28*K99 | L29: =+$E28*L99 | M29: =+$E28*M99 | N29: =+$E28*N99 | O29: =+$E28*O99 | ... S29: =+$E28*S99 | T29: =SUM(H28:S28) | V29: =+$E28*V99 | W29: =+$E28*W99 | X29: =+$E28*X99 | Y29: =+$E28*Y99 | Z29: =+$E28*Z99 | AA29: =+$E28*AA99 | AB29: =+$E28*AB99 | AC29: =+$E28*AC99 | ... AG29: =+$E28*AG99 | AH29: =SUM(V28:AG28) | AJ29: =+AH28+T28
B30: Boleta Honorarios | C30: 4.6 | D30: Encargado territorial RRHH | E30: =+Supuestos!E32 | H30: =+$E29*H100 | I30: =+$E29*I100 | J30: =+$E29*J100 | K30: =+$E29*K100 | L30: =+$E29*L100 | M30: =+$E29*M100 | N30: =+$E29*N100 | O30: =+$E29*O100 | ... S30: =+$E29*S100 | T30: =SUM(H29:S29) | V30: =+$E29*V100 | W30: =+$E29*W100 | X30: =+$E29*X100 | Y30: =+$E29*Y100 | Z30: =+$E29*Z100 | AA30: =+$E29*AA100 | AB30: =+$E29*AB100 | AC30: =+$E29*AC100 | ... AG30: =+$E29*AG100 | AH30: =SUM(V29:AG29) | AJ30: =+AH29+T29
B31: Boleta Honorarios | C31: 4.7 | D31: Apoyo Financiero de proyecto | E31: =+Supuestos!E33 | H31: =+$E30*H101 | I31: =+$E30*I101 | J31: =+$E30*J101 | K31: =+$E30*K101 | L31: =+$E30*L101 | M31: =+$E30*M101 | N31: =+$E30*N101 | O31: =+$E30*O101 | ... S31: =+$E30*S101 | T31: =SUM(H30:S30) | V31: =+$E30*V101 | W31: =+$E30*W101 | X31: =+$E30*X101 | Y31: =+$E30*Y101 | Z31: =+$E30*Z101 | AA31: =+$E30*AA101 | AB31: =+$E30*AB101 | AC31: =+$E30*AC101 | ... AG31: =+$E30*AG101 | AH31: =SUM(V30:AG30) | AJ31: =+AH30+T30
B32: Boleta Honorarios | C32: 4.8 | E32: =+Supuestos!E34 | T32: =SUM(H31:S31) | AH32: =SUM(V31:AG31) | AJ32: =+AH31+T31
B33: Boleta Honorarios | T33: =SUM(H32:S32) | AH33: =SUM(V32:AG32) | AJ33: =+AH32+T32
C34: 5. | D34: Alquileres RRCC | E34: =+Supuestos!E36 | F34: =+F104 | H34: =+SUM(H34:H35) | I34: =+SUM(I34:I35) | J34: =+SUM(J34:J35) | K34: =+SUM(K34:K35) | L34: =+SUM(L34:L35) | M34: =+SUM(M34:M35) | N34: =+SUM(N34:N35) | O34: =+SUM(O34:O35) | ... S34: =+SUM(S34:S35) | T34: =SUM(H33:S33) | V34: =+SUM(V34:V35) | W34: =+SUM(W34:W35) | X34: =+SUM(X34:X35) | Y34: =+SUM(Y34:Y35) | Z34: =+SUM(Z34:Z35) | AA34: =+SUM(AA34:AA35) | AB34: =+SUM(AB34:AB35) | AC34: =+SUM(AC34:AC35) | ... AG34: =+SUM(AG34:AG35) | AH34: =SUM(V33:AG33) | AJ34: =+AH33+T33
B35: Factura | C35: 5.1 | D35: Arriendo vehículo diario - RRCC | E35: =+Supuestos!G37 | F35: =+F105 | H35: =+$E34*H105 | I35: =+$E34*I105 | J35: =+$E34*J105 | K35: =+$E34*K105 | L35: =+$E34*L105 | M35: =+$E34*M105 | N35: =+$E34*N105 | O35: =+$E34*O105 | ... S35: =+$E34*S105 | T35: =SUM(H34:S34) | V35: =+$E34*V105 | W35: =+$E34*W105 | X35: =+$E34*X105 | Y35: =+$E34*Y105 | Z35: =+$E34*Z105 | AA35: =+$E34*AA105 | AB35: =+$E34*AB105 | AC35: =+$E34*AC105 | ... AG35: =+$E34*AG105 | AH35: =SUM(V34:AG34) | AJ35: =+AH34+T34
B36: Factura | C36: 5.2 | D36: Vehiculo RRCC | E36: =+Supuestos!G38 | F36: =+F106 | H36: =+$E35*H106 | I36: =+$E35*I106 | J36: =+$E35*J106 | K36: =+$E35*K106 | L36: =+$E35*L106 | M36: =+$E35*M106 | N36: =+$E35*N106 | O36: =+$E35*O106 | ... S36: =+$E35*S106 | T36: =SUM(H35:S35) | V36: =+$E35*V106 | W36: =+$E35*W106 | X36: =+$E35*X106 | Y36: =+$E35*Y106 | Z36: =+$E35*Z106 | AA36: =+$E35*AA106 | AB36: =+$E35*AB106 | AC36: =+$E35*AC106 | ... AG36: =+$E35*AG106 | AH36: =SUM(V35:AG35) | AJ36: =+AH35+T35
C37: 6. | D37: Alquileres Gestión Técnica | E37: =+Supuestos!E39 | F37: =+F107 | H37: =+SUM(H37:H40) | I37: =+SUM(I37:I40) | J37: =+SUM(J37:J40) | K37: =+SUM(K37:K40) | L37: =+SUM(L37:L40) | M37: =+SUM(M37:M40) | N37: =+SUM(N37:N40) | O37: =+SUM(O37:O40) | ... S37: =+SUM(S37:S40) | T37: =SUM(H36:S36) | V37: =+SUM(V37:V40) | W37: =+SUM(W37:W40) | X37: =+SUM(X37:X40) | Y37: =+SUM(Y37:Y40) | Z37: =+SUM(Z37:Z40) | AA37: =+SUM(AA37:AA40) | AB37: =+SUM(AB37:AB40) | AC37: =+SUM(AC37:AC40) | ... AG37: =+SUM(AG37:AG40) | AH37: =SUM(V36:AG36) | AJ37: =+AH36+T36
B38: Factura | C38: 6.1 | D38: Bodega Terreno | E38: =+Supuestos!G40 | F38: =+F108 | H38: =+$E37*H108 | I38: =+$E37*I108 | J38: =+$E37*J108 | K38: =+$E37*K108 | L38: =+$E37*L108 | M38: =+$E37*M108 | N38: =+$E37*N108 | O38: =+$E37*O108 | ... S38: =+$E37*S108 | T38: =SUM(H37:S37) | V38: =+$E37*V108 | W38: =+$E37*W108 | X38: =+$E37*X108 | Y38: =+$E37*Y108 | Z38: =+$E37*Z108 | AA38: =+$E37*AA108 | AB38: =+$E37*AB108 | AC38: =+$E37*AC108 | ... AG38: =+$E37*AG108 | AH38: =SUM(V37:AG37) | AJ38: =+AH37+T37
B39: Factura | C39: 6.2 | D39: Arriendo vehículo diario - Área Técnica | E39: =+Supuestos!G41 | F39: =+F109 | H39: =+$E38*H109 | I39: =+$E38*I109 | J39: =+$E38*J109 | K39: =+$E38*K109 | L39: =+$E38*L109 | M39: =+$E38*M109 | N39: =+$E38*N109 | O39: =+$E38*O109 | ... S39: =+$E38*S109 | T39: =SUM(H38:S38) | V39: =+$E38*V109 | W39: =+$E38*W109 | X39: =+$E38*X109 | Y39: =+$E38*Y109 | Z39: =+$E38*Z109 | AA39: =+$E38*AA109 | AB39: =+$E38*AB109 | AC39: =+$E38*AC109 | ... AG39: =+$E38*AG109 | AH39: =SUM(V38:AG38) | AJ39: =+AH38+T38
B40: Factura | C40: 6.3 | D40: Vehiculo Instaladores | E40: =+Supuestos!G42 | F40: =+F110 | H40: =+$E39*H110 | I40: =+$E39*I110 | J40: =+$E39*J110 | K40: =+$E39*K110 | L40: =+$E39*L110 | M40: =+$E39*M110 | N40: =+$E39*N110 | O40: =+$E39*O110 | ... S40: =+$E39*S110 | T40: =SUM(H39:S39) | V40: =+$E39*V110 | W40: =+$E39*W110 | X40: =+$E39*X110 | Y40: =+$E39*Y110 | Z40: =+$E39*Z110 | AA40: =+$E39*AA110 | AB40: =+$E39*AB110 | AC40: =+$E39*AC110 | ... AG40: =+$E39*AG110 | AH40: =SUM(V39:AG39) | AJ40: =+AH39+T39
B41: Factura | C41: 6.4 | D41: Vehiculo Transporte (Maxus Deliver 9) | E41: =+Supuestos!G43 | F41: =+F111 | H41: =+$E40*H111 | I41: =+$E40*I111 | J41: =+$E40*J111 | K41: =+$E40*K111 | L41: =+$E40*L111 | M41: =+$E40*M111 | N41: =+$E40*N111 | O41: =+$E40*O111 | ... S41: =+$E40*S111 | T41: =SUM(H40:S40) | V41: =+$E40*V111 | W41: =+$E40*W111 | X41: =+$E40*X111 | Y41: =+$E40*Y111 | Z41: =+$E40*Z111 | AA41: =+$E40*AA111 | AB41: =+$E40*AB111 | AC41: =+$E40*AC111 | ... AG41: =+$E40*AG111 | AH41: =SUM(V40:AG40) | AJ41: =+AH40+T40
C42: 7. | D42: Transporte | E42: =+Supuestos!E44 | F42: =+F112 | H42: =+SUM(H42:H48) | I42: =+SUM(I42:I48) | J42: =+SUM(J42:J48) | K42: =+SUM(K42:K48) | L42: =+SUM(L42:L48) | M42: =+SUM(M42:M48) | N42: =+SUM(N42:N48) | O42: =+SUM(O42:O48) | ... S42: =+SUM(S42:S48) | T42: =SUM(H41:S41) | V42: =+SUM(V42:V48) | W42: =+SUM(W42:W48) | X42: =+SUM(X42:X48) | Y42: =+SUM(Y42:Y48) | Z42: =+SUM(Z42:Z48) | AA42: =+SUM(AA42:AA48) | AB42: =+SUM(AB42:AB48) | AC42: =+SUM(AC42:AC48) | ... AG42: =+SUM(AG42:AG48) | AH42: =SUM(V41:AG41) | AJ42: =+AH41+T41
...

Sheet Antecedentes Programa
A1: ANTECEDENTES Y CONTEXTO DEL PROGRAMA — LUZ EN CASA
A3: Antecedentes y Contexto del Programa
A4: Luz en Casa · GORE Coquimbo · Fundación acciona.org
A5: Fuente: Minuta de Proyecto + Minuta Técnica de Proyecto
B7: 1. Antecedentes y contextualización
B8: El programa Luz en Casa es una iniciativa de ACCIONA.org, la fundación corporativa de ACCIONA, orientada a llevar soluciones de electrificación con sistemas fotovoltaicos domiciliarios a hogares rurales y aislados de Chile que no cuentan con acceso estable a electricidad.
B10: El programa se implementa por primera vez en Chile en 2021, con un proyecto piloto en Caleta Maitencillo, en la Región de Coquimbo. Esta comunidad de pescadores carecía de electricidad o dependía de generadores costosos y de uso limitado. El piloto introdujo un modelo de provisión de servicio adaptado al contexto chileno, incorporando sistemas fotovoltaicos domiciliarios con operación en energía continua como alterna, capaces de alimentar electrodomésticos como refrigeradores.
B12: En 2019, aún existían cerca de 24.556 hogares sin acceso o con acceso parcial a electricidad en Chile, concentrados principalmente en regiones rurales como Coquimbo, donde se registraban cerca de 3.181 viviendas sin electrificación. Las familias dependían de velas, pilas y generadores fósiles, soluciones costosas y poco seguras. Este contexto justificó la implementación de Luz en Casa para proveer energía renovable asequible y permanente.
B14: Tras el piloto, el programa se extendió por toda la Región de Coquimbo, alcanzando comunidades costeras y precordilleranas como Los Vilos, Illapel, Canela, Combarbalá, Monte Patria, Punitaqui y Ovalle. Estas zonas incluyen principalmente familias dedicadas a la pesca, ganadería y agricultura, muy afectadas por el cambio climático.
B16: Entre 2021 y 2025, el programa benefició a más de 800 familias solo en Coquimbo, mejorando las condiciones de vida de más de 2.600 personas en 160 comunidades.
B18: En 2025, la iniciativa se amplió a la Región de Atacama, específicamente a las comunas de Caldera y Copiapó, donde se implementaron sistemas fotovoltaicos en 230 hogares aislados. Esta expansión responde a que aún existen aproximadamente 1.000 viviendas sin acceso a la red eléctrica en el país.
B20: El programa en Chile incorpora un modelo de gestión que garantiza:
B22: • | C22: Mantenimiento continuo de los equipos, asegurado mediante cuotas asequibles aportadas por los usuarios de forma mensual con destino solo a la operación del proyecto.
B24: • | C24: Un sistema de pago adaptado al territorio, utilizando las 30.000 sucursales de Caja Vecina de BancoEstado, facilitando el acceso de familias rurales a un método de pago cercano y simple.
B26: Este modelo asegura la sostenibilidad económica y técnica del programa a largo plazo, ya que con el pago de cuota se asegura un cambio de elementos a fin de su vida útil sin un costo extra para los usuarios.
B28: El acceso a electricidad estable ha promovido:
B30: • | C30: Mejora en salud, educación y conectividad digital de comunidades aisladas.
B32: • | C32: Desarrollo de actividades productivas, como conservación de alimentos, elaboración de productos y trabajo nocturno.
B34: • | C34: Reducción del uso de combustibles fósiles y, con ello, de la contaminación y los costos operativos familiares.
B36: • | C36: Generación de empleo local en técnicos eléctricos locales, a cargo de labores de mantenimiento y atención de usuarios.
B39: 2. Forma de trabajo
B40: El éxito del programa Luz en Casa en Chile se basa en una estructura operativa integral que combina coordinación institucional, trabajo comunitario, logística eficiente y un modelo de gestión orientado a la sostenibilidad.
B42: 2.1. Relacionamiento institucional y comunitario
B43: La primera etapa del programa consiste en establecer una red de coordinación con actores relevantes del territorio:
B45: 2.1.1. Instituciones públicas
B46: • | C46: Municipalidades: se coordinan acciones para diagnóstico territorial, acceso a información local y apoyo en la identificación de comunidades prioritarias.
B47: • | C47: Superintendencia de Electricidad y Combustibles (SEC): se asegura el cumplimiento de normativas y estándares técnicos.
B48: • | C48: Otros organismos sectoriales: Subsecretarías Regionales, Gobernaciones Regionales, INDAP y programas sociales de instituciones públicas.
B50: 2.1.2. Organizaciones sociales y comunitarias
B51: • | C51: Presidentes de comunidades y juntas de vecinos: actores clave en la convocatoria, registro y validación de beneficiarios.
B52: • | C52: Centros de Energía Fotovoltaica (CEF): estructuras comunitarias conformadas por Fundación acciona.org que apoyan el uso, supervisión y mantenimiento básico del sistema.
B53: • | C53: Actores productivos locales: asociaciones de pescadores, crianceros y agricultores que requieren energía para mejorar sus capacidades productivas.
B55: Esta fase permite asegurar legitimidad territorial, transparencia y participación de la comunidad en todo el proceso.
B57: 2.2. Trabajo comunitario
B58: El trabajo directo con las familias es esencial para asegurar un diseño adecuado y sostenible del proyecto. Incluye las siguientes actividades:
B60: • | C60: Reuniones con autoridades locales para presentar el programa, sus beneficios y requerimientos.
B61: • | C61: Identificación de comunidades y levantamiento documental: información preliminar de necesidades energéticas para proyectar trabajo de gabinete y recolección en terreno.
B62: • | C62: Sensibilización y jornadas informativas: se presenta el modelo de servicio, costos, equipos y compromisos mutuos, incluyendo alcances y limitaciones del equipo, registrando solo a quienes con esa información sigan interesados.
B63: • | C63: Registro de fichas de interés: las familias formalizan su intención de participar mediante documento físico que pasa a base de datos. Se revisa condición de vivienda y propiedad de terreno (requisito: residente permanente).
B64: • | C64: Encuestas socioeconómicas para priorizar hogares según vulnerabilidad, dispersión geográfica y/o urgencia energética.
...

Sheet Flujo Neto
A1: FLUJO NETO (PRECIOS NETO SIN IVA) — LUZ EN CASA · GORE COQUIMBO
D4: PRECIOS NETO | P4: Voluntariado | Q4: Voluntariado | R4: Voluntariado
A5: Fuente: Minuta de Proyecto + Minuta Técnica de Proyecto | B5: Forma pago | C5: Nivel | D5: Item | E5: NETO | H5: 46023 | I5: 46054 | J5: 46082 | K5: 46113 | L5: 46143 | M5: 46174 | N5: 46204 | O5: 46235 | P5: 46266 | Q5: 46296 | R5: 46327 | S5: 46357 | T5: 2026 | V5: 46388 | W5: 46419 | X5: 46447 | Y5: 46478 | Z5: 46508 | AA5: 46539 | AB5: 46569 | AC5: 46600 | AD5: 46631 | AE5: 46661 | AF5: 46692 | AG5: 46722 | AH5: 2027 | AJ5: TOTAL
C6: 1 | D6: Compras activables ZIMPERTEC | E6: =+Supuestos!E8 | F6: =+F76 | H6: =+SUM(H6:H13) | I6: =+SUM(I6:I13) | J6: =+SUM(J6:J13) | K6: =+SUM(K6:K13) | L6: =+SUM(L6:L13) | M6: =+SUM(M6:M13) | N6: =+SUM(N6:N13) | O6: =+SUM(O6:O13) | ... S6: =+SUM(S6:S13) | T6: =SUM(H5:S5) | V6: =+SUM(V6:V13) | W6: =+SUM(W6:W13) | X6: =+SUM(X6:X13) | Y6: =+SUM(Y6:Y13) | Z6: =+SUM(Z6:Z13) | AA6: =+SUM(AA6:AA13) | AB6: =+SUM(AB6:AB13) | AC6: =+SUM(AC6:AC13) | ... AG6: =+SUM(AG6:AG13) | AH6: =SUM(V5:AG5) | AJ6: =+AH5+T5
B7: Factura | C7: 1.1 | D7: Sistemas AC | E7: =+Supuestos!E9 | F7: =+F77 | H7: =+$E6*H77 | I7: =+$E6*I77 | J7: =+$E6*J77 | K7: =+$E6*K77 | L7: =+$E6*L77 | M7: =+$E6*M77 | N7: =+$E6*N77 | O7: =+$E6*O77 | ... S7: =+$E6*S77 | V7: =+$E6*V77 | W7: =+$E6*W77 | X7: =+$E6*X77 | Y7: =+$E6*Y77 | Z7: =+$E6*Z77 | AA7: =+$E6*AA77 | AB7: =+$E6*AB77 | AC7: =+$E6*AC77 | ... AG7: =+$E6*AG77
B8: Factura | C8: 1.2 | D8: Paneles | E8: =+Supuestos!E10 | F8: =+F78 | H8: =+$E7*H78 | I8: =+$E7*I78 | J8: =+$E7*J78 | K8: =+$E7*K78 | L8: =+$E7*L78 | M8: =+$E7*M78 | N8: =+$E7*N78 | O8: =+$E7*O78 | ... S8: =+$E7*S78 | V8: =+$E7*V78 | W8: =+$E7*W78 | X8: =+$E7*X78 | Y8: =+$E7*Y78 | Z8: =+$E7*Z78 | AA8: =+$E7*AA78 | AB8: =+$E7*AB78 | AC8: =+$E7*AC78 | ... AG8: =+$E7*AG78
B9: Factura | C9: 1.3 | D9: Lamparas | E9: =+Supuestos!E11 | F9: =+F79 | H9: =+$E8*H79 | I9: =+$E8*I79 | J9: =+$E8*J79 | K9: =+$E8*K79 | L9: =+$E8*L79 | M9: =+$E8*M79 | N9: =+$E8*N79 | O9: =+$E8*O79 | ... S9: =+$E8*S79 | V9: =+$E8*V79 | W9: =+$E8*W79 | X9: =+$E8*X79 | Y9: =+$E8*Y79 | Z9: =+$E8*Z79 | AA9: =+$E8*AA79 | AB9: =+$E8*AB79 | AC9: =+$E8*AC79 | ... AG9: =+$E8*AG79
B10: El programa se implementa por primera vez en Chile en 2021, con un proyecto piloto en Caleta Maitencillo, en la Región de Coquimbo. Esta comunidad de pescadores carecía de electricidad o dependía de generadores costosos y de uso limitado. El piloto introdujo un modelo de provisión de servicio adaptado al contexto chileno, incorporando sistemas fotovoltaicos domiciliarios con operación en energía continua como alterna, capaces de alimentar electrodomésticos como refrigeradores. | C10: 1.4 | D10: Hardware Monitoreo | E10: =+Supuestos!E12 | F10: =+F80 | H10: =+$E9*H80 | I10: =+$E9*I80 | J10: =+$E9*J80 | K10: =+$E9*K80 | L10: =+$E9*L80 | M10: =+$E9*M80 | N10: =+$E9*N80 | O10: =+$E9*O80 | ... S10: =+$E9*S80 | V10: =+$E9*V80 | W10: =+$E9*W80 | X10: =+$E9*X80 | Y10: =+$E9*Y80 | Z10: =+$E9*Z80 | AA10: =+$E9*AA80 | AB10: =+$E9*AB80 | AC10: =+$E9*AC80 | ... AG10: =+$E9*AG80
B11: Factura | C11: 1.5 | D11: Software Monitoreo | E11: =+Supuestos!E13 | F11: =+F81 | H11: =+$E10*H81 | I11: =+$E10*I81 | J11: =+$E10*J81 | K11: =+$E10*K81 | L11: =+$E10*L81 | M11: =+$E10*M81 | N11: =+$E10*N81 | O11: =+$E10*O81 | ... S11: =+$E10*S81 | V11: =+$E10*V81 | W11: =+$E10*W81 | X11: =+$E10*X81 | Y11: =+$E10*Y81 | Z11: =+$E10*Z81 | AA11: =+$E10*AA81 | AB11: =+$E10*AB81 | AC11: =+$E10*AC81 | ... AG11: =+$E10*AG81
B12: Factura | C12: 1.6 | D12: Repuestos | E12: =+Supuestos!E14 | F12: =+F82 | H12: =+$E11*H82 | I12: =+$E11*I82 | J12: =+$E11*J82 | K12: =+$E11*K82 | L12: =+$E11*L82 | M12: =+$E11*M82 | N12: =+$E11*N82 | O12: =+$E11*O82 | ... S12: =+$E11*S82 | V12: =+$E11*V82 | W12: =+$E11*W82 | X12: =+$E11*X82 | Y12: =+$E11*Y82 | Z12: =+$E11*Z82 | AA12: =+$E11*AA82 | AB12: =+$E11*AB82 | AC12: =+$E11*AC82 | ... AG12: =+$E11*AG82
B13: Factura | C13: 1.7 | D13: Flete | E13: =+Supuestos!E15 | F13: =+F83 | H13: =+$E12*H83 | I13: =+$E12*I83 | J13: =+$E12*J83 | K13: =+$E12*K83 | L13: =+$E12*L83 | M13: =+$E12*M83 | N13: =+$E12*N83 | O13: =+$E12*O83 | ... S13: =+$E12*S83 | V13: =+$E12*V83 | W13: =+$E12*W83 | X13: =+$E12*X83 | Y13: =+$E12*Y83 | Z13: =+$E12*Z83 | AA13: =+$E12*AA83 | AB13: =+$E12*AB83 | AC13: =+$E12*AC83 | ... AG13: =+$E12*AG83
B14: Factura | C14: 7.2 | D14: Transporte DESCONSOLIDADO | E14: =+Supuestos!E16 | F14: =+F84 | H14: =+$E13*H84 | I14: =+$E13*I84 | J14: =+$E13*J84 | K14: =+$E13*K84 | L14: =+$E13*L84 | M14: =+$E13*M84 | N14: =+$E13*N84 | O14: =+$E13*O84 | ... S14: =+$E13*S84 | V14: =+$E13*V84 | W14: =+$E13*W84 | X14: =+$E13*X84 | Y14: =+$E13*Y84 | Z14: =+$E13*Z84 | AA14: =+$E13*AA84 | AB14: =+$E13*AB84 | AC14: =+$E13*AC84 | ... AG14: =+$E13*AG84
B15: Factura | C15: 7.5 | D15: Grúa en Origen | E15: =+Supuestos!E17 | F15: =+F85 | H15: =+$E14*H85 | I15: =+$E14*I85 | J15: =+$E14*J85 | K15: =+$E14*K85 | L15: =+$E14*L85 | M15: =+$E14*M85 | N15: =+$E14*N85 | O15: =+$E14*O85 | ... S15: =+$E14*S85 | V15: =+$E14*V85 | W15: =+$E14*W85 | X15: =+$E14*X85 | Y15: =+$E14*Y85 | Z15: =+$E14*Z85 | AA15: =+$E14*AA85 | AB15: =+$E14*AB85 | AC15: =+$E14*AC85 | ... AG15: =+$E14*AG85
B16: Factura | C16: 7.6 | D16: Grúa en Punto Destino (6 Horas) | E16: =+Supuestos!E18 | F16: =+F86 | H16: =+$E15*H86 | I16: =+$E15*I86 | J16: =+$E15*J86 | K16: =+$E15*K86 | L16: =+$E15*L86 | M16: =+$E15*M86 | N16: =+$E15*N86 | O16: =+$E15*O86 | ... S16: =+$E15*S86 | V16: =+$E15*V86 | W16: =+$E15*W86 | X16: =+$E15*X86 | Y16: =+$E15*Y86 | Z16: =+$E15*Z86 | AA16: =+$E15*AA86 | AB16: =+$E15*AB86 | AC16: =+$E15*AC86 | ... AG16: =+$E15*AG86
C17: 2 | D17: Insumos Instalación | E17: =+Supuestos!E19 | F17: =+F87 | H17: =+SUM(H17:H19) | I17: =+SUM(I17:I19) | J17: =+SUM(J17:J19) | K17: =+SUM(K17:K19) | L17: =+SUM(L17:L19) | M17: =+SUM(M17:M19) | N17: =+SUM(N17:N19) | O17: =+SUM(O17:O19) | ... S17: =+SUM(S17:S19) | T17: =SUM(H16:S16) | V17: =+SUM(V17:V19) | W17: =+SUM(W17:W19) | X17: =+SUM(X17:X19) | Y17: =+SUM(Y17:Y19) | Z17: =+SUM(Z17:Z19) | AA17: =+SUM(AA17:AA19) | AB17: =+SUM(AB17:AB19) | AC17: =+SUM(AC17:AC19) | ... AG17: =+SUM(AG17:AG19) | AH17: =SUM(V16:AG16) | AJ17: =+AH16+T16
B18: Factura | C18: 2.1 | D18: Estructura | E18: =+Supuestos!E20 | F18: =+F88 | H18: =+$E17*H88 | I18: =+$E17*I88 | J18: =+$E17*J88 | K18: =+$E17*K88 | L18: =+$E17*L88 | M18: =+$E17*M88 | N18: =+$E17*N88 | O18: =+$E17*O88 | ... S18: =+$E17*S88 | V18: =+$E17*V88 | W18: =+$E17*W88 | X18: =+$E17*X88 | Y18: =+$E17*Y88 | Z18: =+$E17*Z88 | AA18: =+$E17*AA88 | AB18: =+$E17*AB88 | AC18: =+$E17*AC88 | ... AG18: =+$E17*AG88
B19: Factura o Boleta | C19: 2.2 | D19: Materiales instalación | E19: =+Supuestos!E21 | F19: =+F89 | H19: =+$E18*H89 | I19: =+$E18*I89 | J19: =+$E18*J89 | K19: =+$E18*K89 | L19: =+$E18*L89 | M19: =+$E18*M89 | N19: =+$E18*N89 | O19: =+$E18*O89 | ... S19: =+$E18*S89 | V19: =+$E18*V89 | W19: =+$E18*W89 | X19: =+$E18*X89 | Y19: =+$E18*Y89 | Z19: =+$E18*Z89 | AA19: =+$E18*AA89 | AB19: =+$E18*AB89 | AC19: =+$E18*AC89 | ... AG19: =+$E18*AG89
B20: Factura o Boleta | C20: 2.3 | D20: Herramientas | E20: =+Supuestos!E22 | F20: =+F90 | H20: =+$E19*H90 | I20: =+$E19*I90 | J20: =+$E19*J90 | K20: =+$E19*K90 | L20: =+$E19*L90 | M20: =+$E19*M90 | N20: =+$E19*N90 | O20: =+$E19*O90 | ... S20: =+$E19*S90 | V20: =+$E19*V90 | W20: =+$E19*W90 | X20: =+$E19*X90 | Y20: =+$E19*Y90 | Z20: =+$E19*Z90 | AA20: =+$E19*AA90 | AB20: =+$E19*AB90 | AC20: =+$E19*AC90 | ... AG20: =+$E19*AG90
C21: 3. | D21: Personal y Servicios | E21: =+Supuestos!E23 | F21: =+F91 | H21: =H21+H22 | I21: =I21+I22 | J21: =J21+J22 | K21: =K21+K22 | L21: =L21+L22 | M21: =M21+M22 | N21: =N21+N22 | O21: =O21+O22 | ... S21: =S21+S22 | T21: =SUM(H20:S20) | V21: =V21+V22 | W21: =W21+W22 | X21: =X21+X22 | Y21: =Y21+Y22 | Z21: =Z21+Z22 | AA21: =AA21+AA22 | AB21: =AB21+AB22 | AC21: =AC21+AC22 | ... AG21: =AG21+AG22 | AH21: =SUM(V20:AG20) | AJ21: =+AH20+T20
B22: Costo Empresa | C22: 3.1 | D22: Planilla Actual | E22: =+Supuestos!E24 | F22: =+F92 | H22: =+$E21*H92 | I22: =+$E21*I92 | J22: =+$E21*J92 | K22: =+$E21*K92 | L22: =+$E21*L92 | M22: =+$E21*M92 | N22: =+$E21*N92 | O22: =+$E21*O92 | ... S22: =+$E21*S92 | V22: =+$E21*V92 | W22: =+$E21*W92 | X22: =+$E21*X92 | Y22: =+$E21*Y92 | Z22: =+$E21*Z92 | AA22: =+$E21*AA92 | AB22: =+$E21*AB92 | AC22: =+$E21*AC92 | ... AG22: =+$E21*AG92
C23: 3.2 | D23: Descarga Estructura | E23: =+Supuestos!E25 | H23: =+$E22*H93 | I23: =+$E22*I93 | J23: =+$E22*J93 | K23: =+$E22*K93 | L23: =+$E22*L93 | M23: =+$E22*M93 | N23: =+$E22*N93 | O23: =+$E22*O93 | ... S23: =+$E22*S93 | V23: =+$E22*V93 | W23: =+$E22*W93 | X23: =+$E22*X93 | Y23: =+$E22*Y93 | Z23: =+$E22*Z93 | AA23: =+$E22*AA93 | AB23: =+$E22*AB93 | AC23: =+$E22*AC93 | ... AG23: =+$E22*AG93
C24: 4. | D24: Servicios Profesionales | E24: =+Supuestos!E26 | F24: =+F94 | H24: =+SUM(H24:H31) | I24: =+SUM(I24:I31) | J24: =+SUM(J24:J31) | K24: =+SUM(K24:K31) | L24: =+SUM(L24:L31) | M24: =+SUM(M24:M31) | N24: =+SUM(N24:N31) | O24: =+SUM(O24:O31) | ... S24: =+SUM(S24:S31) | T24: =SUM(H23:S23) | V24: =+SUM(V24:V31) | W24: =+SUM(W24:W31) | X24: =+SUM(X24:X31) | Y24: =+SUM(Y24:Y31) | Z24: =+SUM(Z24:Z31) | AA24: =+SUM(AA24:AA31) | AB24: =+SUM(AB24:AB31) | AC24: =+SUM(AC24:AC31) | ... AG24: =+SUM(AG24:AG31) | AH24: =SUM(V23:AG23) | AJ24: =+AH23+T23
B25: Boleta Honorarios | C25: 4.1 | D25: Encargado de Logistica y Bodega | E25: =+Supuestos!E27 | F25: =+F95 | H25: =+$E24*H95 | I25: =+$E24*I95 | J25: =+$E24*J95 | K25: =+$E24*K95 | L25: =+$E24*L95 | M25: =+$E24*M95 | N25: =+$E24*N95 | O25: =+$E24*O95 | ... S25: =+$E24*S95 | V25: =+$E24*V95 | W25: =+$E24*W95 | X25: =+$E24*X95 | Y25: =+$E24*Y95 | Z25: =+$E24*Z95 | AA25: =+$E24*AA95 | AB25: =+$E24*AB95 | AC25: =+$E24*AC95 | ... AG25: =+$E24*AG95
B26: Boleta Honorarios | C26: 4.2 | D26: Técnico pago por instalación - Plan A | E26: =+Supuestos!E28 | F26: =+F96 | H26: =+$E25*H96 | I26: =+$E25*I96 | J26: =+$E25*J96 | K26: =+$E25*K96 | L26: =+$E25*L96 | M26: =+$E25*M96 | N26: =+$E25*N96 | O26: =+$E25*O96 | ... S26: =+$E25*S96 | V26: =+$E25*V96 | W26: =+$E25*W96 | X26: =+$E25*X96 | Y26: =+$E25*Y96 | Z26: =+$E25*Z96 | AA26: =+$E25*AA96 | AB26: =+$E25*AB96 | AC26: =+$E25*AC96 | ... AG26: =+$E25*AG96
B27: Boleta Honorarios | C27: 4.3 | D27: Técnico contrato mensual - Plan B | E27: =+Supuestos!E29 | F27: =+F97 | H27: =+$E26*H97 | I27: =+$E26*I97 | J27: =+$E26*J97 | K27: =+$E26*K97 | L27: =+$E26*L97 | M27: =+$E26*M97 | N27: =+$E26*N97 | O27: =+$E26*O97 | ... S27: =+$E26*S97 | V27: =+$E26*V97 | W27: =+$E26*W97 | X27: =+$E26*X97 | Y27: =+$E26*Y97 | Z27: =+$E26*Z97 | AA27: =+$E26*AA97 | AB27: =+$E26*AB97 | AC27: =+$E26*AC97 | ... AG27: =+$E26*AG97
B28: Boleta Honorarios | C28: 4.4 | D28: Ayudante contrato mensual - Plan B | E28: =+Supuestos!E30 | F28: =+F98 | H28: =+$E27*H98 | I28: =+$E27*I98 | J28: =+$E27*J98 | K28: =+$E27*K98 | L28: =+$E27*L98 | M28: =+$E27*M98 | N28: =+$E27*N98 | O28: =+$E27*O98 | ... S28: =+$E27*S98 | V28: =+$E27*V98 | W28: =+$E27*W98 | X28: =+$E27*X98 | Y28: =+$E27*Y98 | Z28: =+$E27*Z98 | AA28: =+$E27*AA98 | AB28: =+$E27*AB98 | AC28: =+$E27*AC98 | ... AG28: =+$E27*AG98
B29: Boleta Honorarios | C29: 4.5 | D29: Personal apoyo Planos TE1 | E29: =+Supuestos!E31 | F29: =+F99 | H29: =+$E28*H99 | I29: =+$E28*I99 | J29: =+$E28*J99 | K29: =+$E28*K99 | L29: =+$E28*L99 | M29: =+$E28*M99 | N29: =+$E28*N99 | O29: =+$E28*O99 | ... S29: =+$E28*S99 | V29: =+$E28*V99 | W29: =+$E28*W99 | X29: =+$E28*X99 | Y29: =+$E28*Y99 | Z29: =+$E28*Z99 | AA29: =+$E28*AA99 | AB29: =+$E28*AB99 | AC29: =+$E28*AC99 | ... AG29: =+$E28*AG99
B30: Boleta Honorarios | C30: 4.6 | D30: Encargado territorial RRHH | E30: =Supuestos!E32 | H30: =+$E29*H100 | I30: =+$E29*I100 | J30: =+$E29*J100 | K30: =+$E29*K100 | L30: =+$E29*L100 | M30: =+$E29*M100 | N30: =+$E29*N100 | O30: =+$E29*O100 | ... S30: =+$E29*S100 | V30: =+$E29*V100 | W30: =+$E29*W100 | X30: =+$E29*X100 | Y30: =+$E29*Y100 | Z30: =+$E29*Z100 | AA30: =+$E29*AA100 | AB30: =+$E29*AB100 | AC30: =+$E29*AC100 | ... AG30: =+$E29*AG100
B31: Boleta Honorarios | C31: 4.7 | D31: Apoyo Financiero de proyecto | E31: =Supuestos!E33 | H31: =+$E30*H101 | I31: =+$E30*I101 | J31: =+$E30*J101 | K31: =+$E30*K101 | L31: =+$E30*L101 | M31: =+$E30*M101 | N31: =+$E30*N101 | O31: =+$E30*O101 | ... S31: =+$E30*S101 | V31: =+$E30*V101 | W31: =+$E30*W101 | X31: =+$E30*X101 | Y31: =+$E30*Y101 | Z31: =+$E30*Z101 | AA31: =+$E30*AA101 | AB31: =+$E30*AB101 | AC31: =+$E30*AC101 | ... AG31: =+$E30*AG101
B32: Boleta Honorarios | C32: 4.8 | E32: =Supuestos!E34 | H32: =+$E31*H102 | I32: =+$E31*I102 | J32: =+$E31*J102 | K32: =+$E31*K102 | L32: =+$E31*L102 | M32: =+$E31*M102 | N32: =+$E31*N102 | O32: =+$E31*O102 | ... S32: =+$E31*S102 | V32: =+$E31*V102 | W32: =+$E31*W102 | X32: =+$E31*X102 | Y32: =+$E31*Y102 | Z32: =+$E31*Z102 | AA32: =+$E31*AA102 | AB32: =+$E31*AB102 | AC32: =+$E31*AC102 | ... AG32: =+$E31*AG102
C34: 5. | D34: Alquileres RRCC | E34: =+Supuestos!E36 | F34: =+F104 | H34: =+SUM(H34:H35) | I34: =+SUM(I34:I35) | J34: =+SUM(J34:J35) | K34: =+SUM(K34:K35) | L34: =+SUM(L34:L35) | M34: =+SUM(M34:M35) | N34: =+SUM(N34:N35) | O34: =+SUM(O34:O35) | ... S34: =+SUM(S34:S35) | T34: =SUM(H33:S33) | V34: =+SUM(V34:V35) | W34: =+SUM(W34:W35) | X34: =+SUM(X34:X35) | Y34: =+SUM(Y34:Y35) | Z34: =+SUM(Z34:Z35) | AA34: =+SUM(AA34:AA35) | AB34: =+SUM(AB34:AB35) | AC34: =+SUM(AC34:AC35) | ... AG34: =+SUM(AG34:AG35) | AH34: =SUM(V33:AG33) | AJ34: =+AH33+T33
B35: Factura | C35: 5.1 | D35: Arriendo vehículo diario - RRCC | E35: =+Supuestos!E37 | F35: =+F105 | H35: =+$E34*H105 | I35: =+$E34*I105 | J35: =+$E34*J105 | K35: =+$E34*K105 | L35: =+$E34*L105 | M35: =+$E34*M105 | N35: =+$E34*N105 | O35: =+$E34*O105 | ... S35: =+$E34*S105 | V35: =+$E34*V105 | W35: =+$E34*W105 | X35: =+$E34*X105 | Y35: =+$E34*Y105 | Z35: =+$E34*Z105 | AA35: =+$E34*AA105 | AB35: =+$E34*AB105 | AC35: =+$E34*AC105 | ... AG35: =+$E34*AG105
B36: Factura | C36: 5.2 | D36: Vehiculo RRCC | E36: =+Supuestos!E38 | F36: =+F106 | H36: =+$E35*H106 | I36: =+$E35*I106 | J36: =+$E35*J106 | K36: =+$E35*K106 | L36: =+$E35*L106 | M36: =+$E35*M106 | N36: =+$E35*N106 | O36: =+$E35*O106 | ... S36: =+$E35*S106 | V36: =+$E35*V106 | W36: =+$E35*W106 | X36: =+$E35*X106 | Y36: =+$E35*Y106 | Z36: =+$E35*Z106 | AA36: =+$E35*AA106 | AB36: =+$E35*AB106 | AC36: =+$E35*AC106 | ... AG36: =+$E35*AG106
